Workbook
Name RASI_List: 'Definitions'!$B$3:$B$7
Name Status_List: 'Definitions'!$B$8:$B$11
Name Type_List: 'Definitions'!$B$12:$B$13
Name Priority_List: 'Definitions'!$B$14:$B$16
Name PRJ_MOT0200: 'Definitions'!$E$3:$E$7
Name PRJ_MOT0300: 'Definitions'!$Z$1
Name PRJ_HSCR01: 'Definitions'!$Z$1
Name PRJ_HBR00: 'Definitions'!$Z$1
Name PRJ_EMBPC00: 'Definitions'!$Z$1
Name PRJ_HCR00: 'Definitions'!$Z$1
Name PRJ_BATERY00: 'Definitions'!$Z$1

Sheet Roadmap
A1: No | B1: Project ID | C1: Project Name | D1: Version | E1: RASI | L1: Start Date | M1: End Date | N1: Status | O1: Notes
E2: Đinh Hoàng Phú | F2: Lê Trí Kiên | G2: Phạm Nam Hiền | H2: Vũ Đăng Khoa | I2: Lê Tiến Anh | J2: Lê Dương Khánh Huy | K2: Tôn Thất Phúc Khánh
A3: 1 | B3: MOT0200 | C3: Dự án phát triển Motion 2 | D3: A | E3: R | F3: R | G3: S | H3: S | I3: R | J3: S | K3: S | N3: Active
A4: 2 | B4: MOT0200 | C4: Dự án phát triển Motion 2 | D4: B | N4: Plan
A5: 3 | B5: MOT0200 | C5: Dự án phát triển Motion 2 | D5: C | N5: Plan
A6: 4 | B6: MOT0300 | C6: Dự án phát triển Motion 3 | F6: R | G6: S | N6: Plan
A7: 5 | B7: HSCR01 | C7: Dự án NC trạm sạc và thay pin cho Robot VMO | F7: R | G7: R | J7: S | N7: Active
A8: 6 | B8: HBR00 | C8: Dự án NC bàn tay Robot VMO | H8: R | N8: Active
A9: 7 | B9: EMBPC00 | C9: Dự án máy tính nhúng VMO | E9: R | N9: Active
A10: 8 | B10: HCR00 | C10: Dự án tay cầm điều khiển từ xa VMO | F10: R | G10: S | H10: S | N10: Plan
A11: 9 | B11: BATERY00 | C11: Dự án Pack pin cho Robot VMO | F11: R | N11: Active

Sheet Tasks
A1: No | B1: Project ID | C1: Project Name | D1: Sub Project | E1: Title | F1: Type | G1: Assignee | H1: Weight | I1: Status | J1: Start Date | K1: Deadline | L1: Notes | M1: Priority
A2: =IF(AND(B2="",D2=""),"",ROW()-1) | B2: BATERY00 | C2: =IF(B2="","",VLOOKUP(B2,Roadmap!$B$3:$C$100,2,FALSE())) | E2: Hợp tác làm mẫu pin với viện pin | F2: Task | G2: kienlt44 | H2: 5 | I2: Doing
A3: =IF(AND(B3="",D3=""),"",ROW()-1) | B3: MOT0200 | C3: =IF(B3="","",VLOOKUP(B3,Roadmap!$B$3:$C$100,2,FALSE())) | D3: Hot Swap | E3: Thiết kế nguyên lý cho mạch Hot Swap | F3: Task | G3: kienlt44 | H3: 5 | I3: Doing
A4: =IF(AND(B4="",D4=""),"",ROW()-1) | B4: MOT0200 | C4: =IF(B4="","",VLOOKUP(B4,Roadmap!$B$3:$C$100,2,FALSE())) | D4: Hot Swap | E4: Thiết kế Layout cho mạch Hot Swap | F4: Task | G4: kienlt44 | H4: 5 | I4: Doing
A5: =IF(AND(B5="",D5=""),"",ROW()-1) | B5: MOT0200 | C5: =IF(B5="","",VLOOKUP(B5,Roadmap!$B$3:$C$100,2,FALSE())) | D5: Hot Swap | E5: Lập trình firmware cho mạch Hot Swap | F5: Task | G5: hienpn2 | H5: 5 | I5: Open
A6: =IF(AND(B6="",D6=""),"",ROW()-1) | B6: EMBPC00 | C6: =IF(B6="","",VLOOKUP(B6,Roadmap!$B$3:$C$100,2,FALSE())) | E6: Hợp tác với đối tác ADC của QC thiết kế máy tính nhúng | F6: Task | G6: phudh2 | H6: 5 | I6: Pending
A7: =IF(AND(B7="",D7=""),"",ROW()-1) | B7: EMBPC00 | C7: =IF(B7="","",VLOOKUP(B7,Roadmap!$B$3:$C$100,2,FALSE())) | E7: Hoàn thành thiết kế schematic và PCB layout | F7: Task | G7: phudh2 | H7: 5 | I7: Doing
A8: =IF(AND(B8="",D8=""),"",ROW()-1) | B8: EMBPC00 | C8: =IF(B8="","",VLOOKUP(B8,Roadmap!$B$3:$C$100,2,FALSE())) | E8: Làm việc với đối tác EMS( Meiko) để sản xuất PCBA | F8: Task | G8: phudh2 | H8: 5 | I8: Doing
A9: =IF(AND(B9="",D9=""),"",ROW()-1) | B9: MOT0200 | C9: =IF(B9="","",VLOOKUP(B9,Roadmap!$B$3:$C$100,2,FALSE())) | D9: PDU | E9: Hoàn thành thiết kế schematic và PCB layout, SOR, FCT test | F9: Task | G9: kienlt44 | H9: 5 | I9: Done
A10: =IF(AND(B10="",D10=""),"",ROW()-1) | B10: MOT0200 | C10: =IF(B10="","",VLOOKUP(B10,Roadmap!$B$3:$C$100,2,FALSE())) | D10: PDU | E10: Upload dữ liệu lên server | F10: Task | G10: kienlt44 | H10: 1 | I10: Done
A11: =IF(AND(B11="",D11=""),"",ROW()-1) | B11: MOT0200 | C11: =IF(B11="","",VLOOKUP(B11,Roadmap!$B$3:$C$100,2,FALSE())) | D11: PDU | E11: Bàn giao dữ liệu cho Kiên | F11: Task | G11: kienlt44 | H11: 1 | I11: Done
A12: =IF(AND(B12="",D12=""),"",ROW()-1) | B12: MOT0200 | C12: =IF(B12="","",VLOOKUP(B12,Roadmap!$B$3:$C$100,2,FALSE())) | D12: PDU | E12: Làm việc với đối tác để sản xuất PCBA | F12: Task | G12: kienlt44 | H12: 5 | I12: Doing
A13: =IF(AND(B13="",D13=""),"",ROW()-1) | B13: MOT0200 | C13: =IF(B13="","",VLOOKUP(B13,Roadmap!$B$3:$C$100,2,FALSE())) | D13: LLB | E13: Hoàn thành thiết kế schematic và PCB layout, SOR, FCT test | F13: Task | G13: phudh2 | H13: 5 | I13: Done
A14: =IF(AND(B14="",D14=""),"",ROW()-1) | B14: MOT0200 | C14: =IF(B14="","",VLOOKUP(B14,Roadmap!$B$3:$C$100,2,FALSE())) | D14: LLB | E14: Upload dữ liệu lên server | F14: Task | G14: phudh2 | H14: 1 | I14: Done
A15: =IF(AND(B15="",D15=""),"",ROW()-1) | B15: MOT0200 | C15: =IF(B15="","",VLOOKUP(B15,Roadmap!$B$3:$C$100,2,FALSE())) | D15: LLB | E15: Bàn giao dữ liệu cho Phú | F15: Task | G15: phudh2 | H15: 1 | I15: Done
A16: =IF(AND(B16="",D16=""),"",ROW()-1) | B16: MOT0200 | C16: =IF(B16="","",VLOOKUP(B16,Roadmap!$B$3:$C$100,2,FALSE())) | D16: LLB | E16: Làm việc với đối tác để sản xuất PCBA | F16: Task | G16: phudh2 | H16: 5 | I16: Doing
A17: =IF(AND(B17="",D17=""),"",ROW()-1) | B17: MOT0200 | C17: =IF(B17="","",VLOOKUP(B17,Roadmap!$B$3:$C$100,2,FALSE())) | D17: Hub Ethernet | E17: Hoàn thành thiết kế schematic và layout PCB | F17: Task | G17: phudh2 | H17: 5 | I17: Doing
A18: =IF(AND(B18="",D18=""),"",ROW()-1) | B18: MOT0200 | C18: =IF(B18="","",VLOOKUP(B18,Roadmap!$B$3:$C$100,2,FALSE())) | D18: Hub Ethernet | E18: Xuất BOM, dữ liệu làm PCBA, SOR, FCT test | F18: Task | G18: phudh2 | H18: 5 | I18: Doing
A19: =IF(AND(B19="",D19=""),"",ROW()-1) | B19: MOT0200 | C19: =IF(B19="","",VLOOKUP(B19,Roadmap!$B$3:$C$100,2,FALSE())) | D19: Hub Ethernet | E19: Làm việc với đối tác để sản xuất PCBA | F19: Task | G19: phudh2 | H19: 5 | I19: Doing
A20: =IF(AND(B20="",D20=""),"",ROW()-1) | B20: MOT0200 | C20: =IF(B20="","",VLOOKUP(B20,Roadmap!$B$3:$C$100,2,FALSE())) | D20: Wire Harness | E20: Tìm và làm việc với đối tác sản xuất dây cáp điện cho Robot | F20: Task | G20: anhlt25 | H20: 10 | I20: Doing
A21: =IF(AND(B21="",D21=""),"",ROW()-1) | B21: HSCR01 | C21: =IF(B21="","",VLOOKUP(B21,Roadmap!$B$3:$C$100,2,FALSE())) | E21: Thiết kế mạch điện cho trạm Thay pin (Nguyên lý và Layout) | F21: Task | G21: kienlt44 | H21: 5 | I21: Doing
A22: =IF(AND(B22="",D22=""),"",ROW()-1) | B22: HSCR01 | C22: =IF(B22="","",VLOOKUP(B22,Roadmap!$B$3:$C$100,2,FALSE())) | E22: Lên BOM List phần Điện tử cho Trạm thay Pin | F22: Task | G22: kienlt44 | H22: 5 | I22: Done
A23: =IF(AND(B23="",D23=""),"",ROW()-1) | B23: HSCR01 | C23: =IF(B23="","",VLOOKUP(B23,Roadmap!$B$3:$C$100,2,FALSE())) | E23: Lập trình cho Trạm thay pin | F23: Task | G23: hienpn2 | H23: 5 | I23: Pending
A24: =IF(AND(B24="",D24=""),"",ROW()-1) | B24: HBR00 | C24: =IF(B24="","",VLOOKUP(B24,Roadmap!$B$3:$C$100,2,FALSE())) | E24: Thiết kế schematic và layout PCB | F24: Task | G24: khoavd11 | H24: 5 | I24: Done
A25: =IF(AND(B25="",D25=""),"",ROW()-1) | B25: HBR00 | C25: =IF(B25="","",VLOOKUP(B25,Roadmap!$B$3:$C$100,2,FALSE())) | E25: Viết FW test mạch bàn tay | F25: Task | G25: khoavd11 | H25: 5 | I25: Doing
A26: =IF(AND(B26="",D26=""),"",ROW()-1) | B26: MOT0200 | C26: =IF(B26="","",VLOOKUP(B26,Roadmap!$B$3:$C$100,2,FALSE())) | E26: Lắp ráp và test Robot | F26: Task | G26: anhlt25 | H26: 5 | I26: Done
A27: =IF(AND(B27="",D27=""),"",ROW()-1) | B27: MOT0200 | C27: =IF(B27="","",VLOOKUP(B27,Roadmap!$B$3:$C$100,2,FALSE())) | D27: LLB | E27: Mua sắm cho dự án Low level control board | F27: Task | G27: kienlt44 | H27: 2 | I27: Doing
A28: =IF(AND(B28="",D28=""),"",ROW()-1) | B28: MOT0200 | C28: =IF(B28="","",VLOOKUP(B28,Roadmap!$B$3:$C$100,2,FALSE())) | D28: PDU | E28: Mua sắm cho dự án PDU | F28: Task | G28: kienlt44 | H28: 2 | I28: Doing
A29: =IF(AND(B29="",D29=""),"",ROW()-1) | B29: MOT0200 | C29: =IF(B29="","",VLOOKUP(B29,Roadmap!$B$3:$C$100,2,FALSE())) | D29: Hot Swap | E29: Mua sắm cho dự án Hot swap board | F29: Task | G29: kienlt44 | H29: 2 | I29: Doing
A30: =IF(AND(B30="",D30=""),"",ROW()-1) | B30: MOT0200 | C30: =IF(B30="","",VLOOKUP(B30,Roadmap!$B$3:$C$100,2,FALSE())) | D30: Hub Ethernet | E30: Mua sắm cho dự án Hub ethernet board | F30: Task | G30: kienlt44 | H30: 2 | I30: Doing
A31: =IF(AND(B31="",D31=""),"",ROW()-1) | B31: MOT0200 | C31: =IF(B31="","",VLOOKUP(B31,Roadmap!$B$3:$C$100,2,FALSE())) | E31: Lựa chọn linh kiện nút nhấn cho Robot Vin Motion 2 | F31: Issue | G31: phudh2 | H31: 2 | I31: Doing
A32: =IF(AND(B32="",D32=""),"",ROW()-1) | B32: MOT0200 | C32: =IF(B32="","",VLOOKUP(B32,Roadmap!$B$3:$C$100,2,FALSE())) | E32: Benchmarking hệ thống điện tử, máy tính, camera các robot trên thế giới (Engine AI, Unitree, Ubitech,…) | F32: Task | G32: khanhttp | H32: 2 | I32: Open
A33: =IF(AND(B33="",D33=""),"",ROW()-1) | B33: MOT0200 | C33: =IF(B33="","",VLOOKUP(B33,Roadmap!$B$3:$C$100,2,FALSE())) | E33: Test Anten đặt trên đầu xem có ổn không | F33: Issue | G33: phudh2 | H33: 2 | I33: Doing
A34: =IF(AND(B34="",D34=""),"",ROW()-1) | B34: MOT0200 | C34: =IF(B34="","",VLOOKUP(B34,Roadmap!$B$3:$C$100,2,FALSE())) | E34: Test loa | F34: Task | G34: phudh2 | H34: 2 | I34: Doing
A35: =IF(AND(B35="",D35=""),"",ROW()-1) | B35: EMBPC00 | C35: =IF(B35="","",VLOOKUP(B35,Roadmap!$B$3:$C$100,2,FALSE())) | E35: Phân tích lỗi máy tính IQ9 - lỗi dòng | F35: Task | G35: kienlt44 | H35: 2 | I35: Doing
A36: =IF(AND(B36="",D36=""),"",ROW()-1) | B36: MOT0200 | C36: =IF(B36="","",VLOOKUP(B36,Roadmap!$B$3:$C$100,2,FALSE())) | E36: Test dây cho Robot | F36: Task | G36: anhlt25 | H36: 2 | I36: Doing
A37: =IF(AND(B37="",D37=""),"",ROW()-1) | B37: MOT0200 | C37: =IF(B37="","",VLOOKUP(B37,Roadmap!$B$3:$C$100,2,FALSE())) | E37: Làm việc nhà máy Vfe | F37: Task | G37: kienlt44 | H37: 2 | I37: Doing
A38: =IF(AND(B38="",D38=""),"",ROW()-1) | B38: MOT0200 | C38: =IF(B38="","",VLOOKUP(B38,Roadmap!$B$3:$C$100,2,FALSE())) | E38: Tiếp nhận và và xử lý lỗi của Robot đang hoạt động tại các P&L | F38: Issue | G38: anhlt25 | H38: 2 | I38: Open
A39: =IF(AND(B39="",D39=""),"",ROW()-1) | C39: =IF(B39="","",VLOOKUP(B39,Roadmap!$B$3:$C$100,2,FALSE()))
A40: =IF(AND(B40="",D40=""),"",ROW()-1) | C40: =IF(B40="","",VLOOKUP(B40,Roadmap!$B$3:$C$100,2,FALSE()))
...

Sheet Definitions
A1: DROPDOWN DEFINITIONS | E1: SUB PROJECT THEO DỰ ÁN
A2: Loại | B2: Giá trị | C2: Mô tả | E2: MOT0200 | F2: MOT0300 | G2: HSCR01 | H2: HBR00 | I2: EMBPC00 | J2: HCR00 | K2: BATERY00
A3: RASI | B3: R | C3: Responsible - Chịu trách nhiệm thực hiện | E3: PDU | F3: (thêm ở đây) | G3: (thêm ở đây) | H3: (thêm ở đây) | I3: (thêm ở đây) | J3: (thêm ở đây) | K3: (thêm ở đây)
B4: A | C4: Accountable - Phê duyệt | E4: LLB
B5: S | C5: Support - Hỗ trợ thực hiện | E5: Hub Ethernet
B6: C | C6: Consulted - Được tham vấn ý kiến | E6: Hot Swap
B7: I | C7: Informed - Được thông báo kết quả | E7: Wire Harness
A8: Status | B8: Open | C8: Chưa bắt đầu | E8: (thêm ở đây)
B9: Doing | C9: Đang thực hiện
B10: Pending | C10: Tạm dừng / Chờ xử lý
B11: Done | C11: Hoàn thành
A12: Type | B12: Task | C12: Công việc
B13: Issue | C13: Vấn đề / Lỗi cần xử lý
A14: Priority | B14: High | C14: Ưu tiên cao - Cần xử lý gấp
B15: Medium | C15: Ưu tiên trung bình
B16: Low | C16: Ưu tiên thấp
A20: Lưu ý: Màu sắc ở đây là bảng tham chiếu. Để đổi màu hiển thị trên Roadmap/Tasks:
A21: → Home → Conditional Formatting → Manage Rules → chọn rule cần sửa → Edit Rule → Format
E23: ① Xóa text "(thêm ở đây)" → gõ tên Sub Project mới vào ô đó ② Vào Formulas → Name Manager → chọn PRJ_<mã dự án> → sửa Refers to cho khớp
